Workbook

Sheet All Tables
B1: Qwen 2.5 Scoring Frequencies | F1: Llama 3.2 Frequencies | J1: Gemma 4 Frequencies | W1: Qwen 2.5 Running Times | Z1: Llama 3.2 Running Times | AC1: Gemma 4 Running Times
B2: Threshold | C2: Range | D2: Frequencies | E2: Average Running Time | F2: Threshold | G2: Range | H2: Frequencies | I2: Average Running Time | J2: Threshold | K2: Range | L2: Frequencies | M2: Average Running Time | W2: Average: | X2: =AVERAGE(qwen2FinalScores[execTime]) -> 6.4959848 | Z2: Average: | AA2: =AVERAGE(llama3FinalScores[execTime]) -> 6.5168926 | AC2: Average: | AD2: =AVERAGE(gemma4FinalScores!D2:D2001) -> 30.800196
B3: 0-9 | C3: 9 | D3: {=FREQUENCY(VALUE(qwen2FinalScores[finalScore]), VALUE(C3:C11))} -> 24 | E3: =AVERAGEIF(qwen2FinalScores[finalScore], "<= 9", qwen2FinalScores[execTime]) -> 12.864639 | F3: 0-9 | G3: 9 | H3: {=FREQUENCY(VALUE(llama3FinalScores[finalScore]), VALUE(G3:G11))} -> 97 | I3: =AVERAGEIF(llama3FinalScores[finalScore], "<= 9", llama3FinalScores[execTime]) -> 8.5977946 | J3: 0-9 | K3: 9 | L3: {=FREQUENCY(VALUE(gemma4FinalScores[finalScore]), VALUE(K3:K11))} -> 431 | M3: =AVERAGEIF(gemma4FinalScores[finalScore], "< 10", gemma4FinalScores!D2:D2001) -> 32.57261 | W3: Qwen 2.5 Scoring Average | Z3: Llama 3.2 Scoring Average | AC3: Gemma 4 Scoring Average
B4: 10-19 | C4: 19 | D4: 211 | E4: =AVERAGEIFS(qwen2FinalScores[execTime], qwen2FinalScores[finalScore], ">= 10", qwen2FinalScores[finalScore], "< 20") -> 4.2619068 | F4: 10-19 | G4: 19 | H4: 98 | I4: =AVERAGEIFS(llama3FinalScores[execTime], llama3FinalScores[finalScore], ">= 10", llama3FinalScores[finalScore], "< 20") -> 6.4014283 | J4: 10-19 | K4: 19 | L4: 49 | M4: =AVERAGEIFS(gemma4FinalScores!D2:D2001, qwen2FinalScores[finalScore], ">= 10", qwen2FinalScores[finalScore], "< 20") -> 28.705429 | W4: Average: | X4: =AVERAGE(qwen2FinalScores[finalScore]) -> 58.575 | Z4: Average: | AA4: =AVERAGE(llama3FinalScores[finalScore]) -> 69.174 | AC4: Average: | AD4: =AVERAGE(gemma4FinalScores[finalScore]) -> 70.0005
B5: 20-29 | C5: 29 | D5: 257 | E5: =AVERAGEIFS(qwen2FinalScores[execTime], qwen2FinalScores[finalScore], ">= 20", qwen2FinalScores[finalScore], "< 30") -> 4.5897046 | F5: 20-29 | G5: 29 | H5: 102 | I5: =AVERAGEIFS(llama3FinalScores[execTime], llama3FinalScores[finalScore], ">= 20", llama3FinalScores[finalScore], "< 30") -> 9.2428334 | J5: 20-29 | K5: 29 | L5: 43 | M5: =AVERAGEIFS(gemma4FinalScores!D2:D2001, qwen2FinalScores[finalScore], ">= 20", qwen2FinalScores[finalScore], "< 30") -> 28.928513
B6: 30-39 | C6: 39 | D6: 272 | E6: =AVERAGEIFS(qwen2FinalScores[execTime], qwen2FinalScores[finalScore], ">= 30", qwen2FinalScores[finalScore], "< 40") -> 4.8717311 | F6: 30-39 | G6: 39 | H6: 120 | I6: =AVERAGEIFS(llama3FinalScores[execTime], llama3FinalScores[finalScore], ">= 30", llama3FinalScores[finalScore], "< 40") -> 6.3557063 | J6: 30-39 | K6: 39 | L6: 40 | M6: =AVERAGEIFS(gemma4FinalScores!D2:D2001, qwen2FinalScores[finalScore], ">= 30", qwen2FinalScores[finalScore], "< 40") -> 29.724607
B7: 40-49 | C7: 49 | D7: 185 | E7: =AVERAGEIFS(qwen2FinalScores[execTime], qwen2FinalScores[finalScore], ">= 40", qwen2FinalScores[finalScore], "< 50") -> 6.1010057 | F7: 40-49 | G7: 49 | H7: 116 | I7: =AVERAGEIFS(llama3FinalScores[execTime], llama3FinalScores[finalScore], ">= 40", llama3FinalScores[finalScore], "< 50") -> 6.2257544 | J7: 40-49 | K7: 49 | L7: 31 | M7: =AVERAGEIFS(gemma4FinalScores!D2:D2001, qwen2FinalScores[finalScore], ">= 40", qwen2FinalScores[finalScore], "< 50") -> 30.189385
B8: 50-59 | C8: 59 | D8: 74 | E8: =AVERAGEIFS(qwen2FinalScores[execTime], qwen2FinalScores[finalScore], ">= 50", qwen2FinalScores[finalScore], "< 60") -> 6.1681573 | F8: 50-59 | G8: 59 | H8: 29 | I8: =AVERAGEIFS(llama3FinalScores[execTime], llama3FinalScores[finalScore], ">= 50", llama3FinalScores[finalScore], "< 60") -> 5.6787824 | J8: 50-59 | K8: 59 | L8: 23 | M8: =AVERAGEIFS(gemma4FinalScores!D2:D2001, qwen2FinalScores[finalScore], ">= 50", qwen2FinalScores[finalScore], "< 60") -> 26.790873
B9: 60-69 | C9: 69 | D9: 43 | E9: =AVERAGEIFS(qwen2FinalScores[execTime], qwen2FinalScores[finalScore], ">= 60", qwen2FinalScores[finalScore], "< 70") -> 6.2593348 | F9: 60-69 | G9: 69 | H9: 50 | I9: =AVERAGEIFS(llama3FinalScores[execTime], llama3FinalScores[finalScore], ">= 60", llama3FinalScores[finalScore], "< 70") -> 5.5219961 | J9: 60-69 | K9: 69 | L9: 32 | M9: =AVERAGEIFS(gemma4FinalScores!D2:D2001, qwen2FinalScores[finalScore], ">= 60", qwen2FinalScores[finalScore], "< 70") -> 26.930133
B10: 70-79 | C10: 79 | D10: 180 | E10: =AVERAGEIFS(qwen2FinalScores[execTime], qwen2FinalScores[finalScore], ">= 70", qwen2FinalScores[finalScore], "< 80") -> 8.3841402 | F10: 70-79 | G10: 79 | H10: 177 | I10: =AVERAGEIFS(llama3FinalScores[execTime], llama3FinalScores[finalScore], ">= 70", llama3FinalScores[finalScore], "< 80") -> 4.9644957 | J10: 70-79 | K10: 79 | L10: 58 | M10: =AVERAGEIFS(gemma4FinalScores!D2:D2001, qwen2FinalScores[finalScore], ">= 70", qwen2FinalScores[finalScore], "< 80") -> 42.422186
B11: 80-89 | C11: 89 | D11: 196 | E11: =AVERAGEIFS(qwen2FinalScores[execTime], qwen2FinalScores[finalScore], ">= 80", qwen2FinalScores[finalScore], "< 90") -> 8.4310721 | F11: 80-89 | G11: 89 | H11: 714 | I11: =AVERAGEIFS(llama3FinalScores[execTime], llama3FinalScores[finalScore], ">= 80", llama3FinalScores[finalScore], "< 90") -> 6.0702091 | J11: 80-89 | K11: 89 | L11: 28 | M11: =AVERAGEIFS(gemma4FinalScores!D2:D2001, qwen2FinalScores[finalScore], ">= 80", qwen2FinalScores[finalScore], "< 90") -> 27.821151
B12: 90-100 | C12: 90 | D12: 558 | E12: =AVERAGEIF(qwen2FinalScores[finalScore], ">= 90", qwen2FinalScores[execTime]) -> 7.6404562 | F12: 90-100 | G12: 90 | H12: 497 | I12: =AVERAGEIF(llama3FinalScores[finalScore], ">= 90", llama3FinalScores[execTime]) -> 7.0245239 | J12: 90-100 | K12: 90 | L12: 1265 | M12: =AVERAGEIF(gemma4FinalScores[finalScore], ">= 90", gemma4FinalScores!D2:D2001) -> 30.646221
B18: Qwen 2.5 Scoring Frequencies | E18: Llama 3.2 Frequencies | H18: Gemma 4 Frequencies | L18: Qwen 2.5 | N18: Llama 3.2 | P18: Gemma 4
B19: Threshold | C19: Range | D19: Frequencies | E19: Threshold | F19: Range | G19: Frequencies | H19: Threshold | I19: Range | J19: Frequencies | L19: Average Accuracy | M19: Running Time | N19: Average Accuracy | O19: Running Time | P19: Average Accuracy | Q19: Running Time
B20: 0-5 | C20: 5 | D20: {=FREQUENCY(VALUE(qwen2FinalScores[finalScore]), VALUE(C20:C38))} -> 21 | E20: 0-5 | F20: 5 | G20: {=FREQUENCY(VALUE(llama3FinalScores[finalScore]), VALUE(F20:F38))} -> 90 | H20: 0-5 | I20: 5 | J20: {=FREQUENCY(VALUE(gemma4FinalScores[finalScore]), VALUE(I20:I38))} -> 427 | L20: =AVERAGE(qwen2FinalScores[finalScore]) -> 58.575 | M20: =AVERAGE(qwen2FinalScores[execTime]) -> 6.4959848 | N20: =AVERAGE(llama3FinalScores[finalScore]) -> 69.174 | O20: =AVERAGE(llama3FinalScores[execTime]) -> 6.5168926 | P20: =AVERAGE(gemma4FinalScores[finalScore]) -> 70.0005 | Q20: =AVERAGE(gemma4FinalScores!D2:D2001) -> 30.800196
B21: 6-10 | C21: 10 | D21: 37 | E21: 6-10 | F21: 10 | G21: 22 | H21: 6-10 | I21: 10 | J21: 23
B22: 11-15 | C22: 15 | D22: 105 | E22: 11-15 | F22: 15 | G22: 67 | H22: 11-15 | I22: 15 | J22: 30
B23: 16-20 | C23: 20 | D23: 152 | E23: 16-20 | F23: 20 | G23: 59 | H23: 16-20 | I23: 20 | J23: 32
B24: 21-25 | C24: 25 | D24: 107 | E24: 21-25 | F24: 25 | G24: 55 | H24: 21-25 | I24: 25 | J24: 10
B25: 26-30 | C25: 30 | D25: 206 | E25: 26-30 | F25: 30 | G25: 73 | H25: 26-30 | I25: 30 | J25: 25
B26: 31-35 | C26: 35 | D26: 14 | E26: 31-35 | F26: 35 | G26: 48 | H26: 31-35 | I26: 35 | J26: 16
B27: 36-40 | C27: 40 | D27: 169 | E27: 36-40 | F27: 40 | G27: 39 | H27: 36-40 | I27: 40 | J27: 24
B28: 41-45 | C28: 45 | D28: 19 | E28: 41-45 | F28: 45 | G28: 47 | H28: 41-45 | I28: 45 | J28: 7
B29: 46-50 | C29: 50 | D29: 149 | E29: 46-50 | F29: 50 | G29: 49 | H29: 46-50 | I29: 50 | J29: 19
B30: 51-55 | C30: 55 | D30: 10 | E30: 51-55 | F30: 55 | G30: 3 | H30: 51-55 | I30: 55 | J30: 3
B31: 56-60 | C31: 60 | D31: 55 | E31: 56-60 | F31: 60 | G31: 19 | H31: 56-60 | I31: 60 | J31: 23
B32: 61-65 | C32: 65 | D32: 9 | E32: 61-65 | F32: 65 | G32: 19 | H32: 61-65 | I32: 65 | J32: 10
... B39: 96-100 | C39: 100 | D39: 488 | E39: 96-100 | F39: 100 | G39: 348 | H39: 96-100 | I39: 100 | J39: 1225

Sheet qwen2FinalScores
A1: llmModel | B1: iteration | C1: finalScore | D1: execTime | E1: programLang | F1: vulnType | G1: vulnSeverity
A2: qwen2.5:3b | B2: 0 | C2: 100 | D2: 8.8047512 | E2: C | F2: Bypass | G2: 6
A3: qwen2.5:3b | B3: 1 | C3: 100 | D3: 17.169964 | E3: C | F3: DoS Overflow +Info | G3: 6.4
A4: qwen2.5:3b | B4: 2 | C4: 75 | D4: 8.1851397 | E4: C | F4: DoS Overflow | G4: 5
A5: qwen2.5:3b | B5: 3 | C5: 30 | D5: 3.1729569 | E5: C | F5: DoS | G5: 4.3
A6: qwen2.5:3b | B6: 4 | C6: 21 | D6: 4.4220972 | E6: C | F6: DoS Exec Code Overflow Mem. Corr. | G6: 7.5
A7: qwen2.5:3b | B7: 5 | C7: 17 | D7: 3.92854 | E7: C | F7: DoS Overflow | G7: 4.3
A8: qwen2.5:3b | B8: 6 | C8: 23 | D8: 3.8095279 | E8: C | F8: DoS Overflow | G8: 4.3
A9: qwen2.5:3b | B9: 7 | C9: 100 | D9: 10.889456 | E9: C | F9: DoS | G9: 6.8
A10: qwen2.5:3b | B10: 8 | C10: 70 | D10: 2.8570457 | E10: C | F10: DoS | G10: 6.8
A11: qwen2.5:3b | B11: 9 | C11: 100 | D11: 10.307254 | E11: C | F11: DoS | G11: 6.8
A12: qwen2.5:3b | B12: 10 | C12: 89 | D12: 10.321041 | E12: C | F12: +Info | G12: 5
A13: qwen2.5:3b | B13: 11 | C13: 16 | D13: 6.2805133 | E13: C | F13: DoS | G13: 4.3
... A36: qwen2.5:3b | B36: 34 | C36: 70 | D36: 7.9207804 | E36: C | F36: Bypass | G36: 7.5
A37: qwen2.5:3b | B37: 35 | C37: 47 | D37: 5.025135 | E37: C | G37: 5
A38: qwen2.5:3b | B38: 36 | C38: 84 | D38: 13.586992 | E38: C | G38: 5
A39: qwen2.5:3b | B39: 37 | C39: 70 | D39: 4.3369772 | E39: CPP | F39: DoS Exec Code Overflow Mem. Corr. | G39: 9.3
A40: qwen2.5:3b | B40: 38 | C40: 80 | D40: 8.3592975 | E40: CPP | F40: DoS Exec Code Overflow | G40: 6.8
A41: qwen2.5:3b | B41: 39 | C41: 100 | D41: 6.5633283 | E41: CPP | F41: DoS Exec Code Overflow | G41: 6.8
A42: qwen2.5:3b | B42: 40 | C42: 37 | D42: 2.8808198 | E42: CPP | F42: DoS Exec Code Overflow | G42: 6.8
A43: qwen2.5:3b | B43: 41 | C43: 37 | D43: 7.8058543 | E43: CPP | F43: DoS Exec Code Overflow | G43: 6.8
A44: qwen2.5:3b | B44: 42 | C44: 19 | D44: 8.4100766 | E44: CPP | F44: DoS Exec Code Overflow | G44: 6.8
A45: qwen2.5:3b | B45: 43 | C45: 100 | D45: 8.620434 | E45: CPP | F45: DoS Exec Code Overflow | G45: 6.8
A46: qwen2.5:3b | B46: 44 | C46: 100 | D46: 9.8068731 | E46: CPP | F46: DoS Exec Code Overflow | G46: 6.8
A47: qwen2.5:3b | B47: 45 | C47: 100 | D47: 3.9263909 | E47: CPP | F47: DoS Exec Code Overflow | G47: 6.8
A48: qwen2.5:3b | B48: 46 | C48: 24 | D48: 3.1220779 | E48: CPP | F48: DoS Exec Code Overflow | G48: 6.8
A49: qwen2.5:3b | B49: 47 | C49: 100 | D49: 3.9531586 | E49: CPP | F49: DoS Exec Code Overflow | G49: 6.8
A50: qwen2.5:3b | B50: 48 | C50: 27 | D50: 3.1811352 | E50: CPP | F50: DoS Exec Code Overflow | G50: 6.8
... A59: qwen2.5:3b | B59: 57 | C59: 70 | D59: 6.8573377 | E59: CPP | F59: DoS Exec Code Overflow | G59: 6.8
A60: qwen2.5:3b | B60: 58 | C60: 100 | D60: 5.2595174 | E60: CPP | G60: 6.8
A61: qwen2.5:3b | B61: 59 | C61: 100 | D61: 5.5029707 | E61: CPP | G61: 6.8
A62: qwen2.5:3b | B62: 60 | C62: 90 | D62: 4.4896467 | E62: C | F62: Overflow | G62: 7.5
A63: qwen2.5:3b | B63: 61 | C63: 17 | D63: 3.0334332 | E63: C | F63: Overflow | G63: 7.5
A64: qwen2.5:3b | B64: 62 | C64: 14 | D64: 2.8822598 | E64: C | F64: Overflow | G64: 5
A65: qwen2.5:3b | B65: 63 | C65: 100 | D65: 4.5128274 | E65: C | F65: Overflow | G65: 5
A66: qwen2.5:3b | B66: 64 | C66: 83 | D66: 16.430559 | E66: C | F66: Overflow | G66: 5
A67: qwen2.5:3b | B67: 65 | C67: 15 | D67: 3.1256864 | E67: C | F67: DoS | G67: 5
A68: qwen2.5:3b | B68: 66 | C68: 80 | D68: 3.0186777 | E68: C | F68: DoS | G68: 5
A69: qwen2.5:3b | B69: 67 | C69: 50 | D69: 3.3259525 | E69: C | F69: DoS | G69: 5
A70: qwen2.5:3b | B70: 68 | C70: 30 | D70: 3.3046052 | E70: C | F70: DoS | G70: 5
...

Sheet llama3FinalScores
A1: llmModel | B1: iteration | C1: finalScore | D1: execTime | E1: programLang | F1: vulnType | G1: vulnSeverity
A2: llama3.2:3b | B2: 0 | C2: 89 | D2: 5.8108811 | E2: C | F2: Bypass | G2: 6
A3: llama3.2:3b | B3: 1 | C3: 0 | D3: 16.738172 | E3: C | F3: DoS Overflow +Info | G3: 6.4
A4: llama3.2:3b | B4: 2 | C4: 48 | D4: 4.9473233 | E4: C | F4: DoS Overflow | G4: 5
A5: llama3.2:3b | B5: 3 | C5: 24 | D5: 2.9469457 | E5: C | F5: DoS | G5: 4.3
A6: llama3.2:3b | B6: 4 | C6: 83 | D6: 4.6149969 | E6: C | F6: DoS Exec Code Overflow Mem. Corr. | G6: 7.5
A7: llama3.2:3b | B7: 5 | C7: 47 | D7: 3.5920579 | E7: C | F7: DoS Overflow | G7: 4.3
A8: llama3.2:3b | B8: 6 | C8: 90 | D8: 3.4555478 | E8: C | F8: DoS Overflow | G8: 4.3
A9: llama3.2:3b | B9: 7 | C9: 33 | D9: 9.4163043 | E9: C | F9: DoS | G9: 6.8
A10: llama3.2:3b | B10: 8 | C10: 83 | D10: 3.186043 | E10: C | F10: DoS | G10: 6.8
A11: llama3.2:3b | B11: 9 | C11: 14 | D11: 6.4211681 | E11: C | F11: DoS | G11: 6.8
A12: llama3.2:3b | B12: 10 | C12: 83 | D12: 5.3175404 | E12: C | F12: +Info | G12: 5
A13: llama3.2:3b | B13: 11 | C13: 23 | D13: 5.7716374 | E13: C | F13: DoS | G13: 4.3
... A36: llama3.2:3b | B36: 34 | C36: 83 | D36: 7.7426388 | E36: C | F36: Bypass | G36: 7.5
A37: llama3.2:3b | B37: 35 | C37: 100 | D37: 11.721439 | E37: C | G37: 5
A38: llama3.2:3b | B38: 36 | C38: 85 | D38: 9.8105209 | E38: C | G38: 5
A39: llama3.2:3b | B39: 37 | C39: 89 | D39: 3.9843721 | E39: CPP | F39: DoS Exec Code Overflow Mem. Corr. | G39: 9.3
A40: llama3.2:3b | B40: 38 | C40: 50 | D40: 15.378109 | E40: CPP | F40: DoS Exec Code Overflow | G40: 6.8
A41: llama3.2:3b | B41: 39 | C41: 100 | D41: 6.3129947 | E41: CPP | F41: DoS Exec Code Overflow | G41: 6.8
A42: llama3.2:3b | B42: 40 | C42: 83 | D42: 2.747102 | E42: CPP | F42: DoS Exec Code Overflow | G42: 6.8
A43: llama3.2:3b | B43: 41 | C43: 100 | D43: 7.1814091 | E43: CPP | F43: DoS Exec Code Overflow | G43: 6.8
A44: llama3.2:3b | B44: 42 | C44: 83 | D44: 8.1388493 | E44: CPP | F44: DoS Exec Code Overflow | G44: 6.8
A45: llama3.2:3b | B45: 43 | C45: 70 | D45: 7.5656478 | E45: CPP | F45: DoS Exec Code Overflow | G45: 6.8
A46: llama3.2:3b | B46: 44 | C46: 88 | D46: 9.3233805 | E46: CPP | F46: DoS Exec Code Overflow | G46: 6.8
A47: llama3.2:3b | B47: 45 | C47: 87 | D47: 3.7389011 | E47: CPP | F47: DoS Exec Code Overflow | G47: 6.8
A48: llama3.2:3b | B48: 46 | C48: 95 | D48: 2.8472934 | E48: CPP | F48: DoS Exec Code Overflow | G48: 6.8
A49: llama3.2:3b | B49: 47 | C49: 89 | D49: 3.745815 | E49: CPP | F49: DoS Exec Code Overflow | G49: 6.8
A50: llama3.2:3b | B50: 48 | C50: 90 | D50: 2.7719662 | E50: CPP | F50: DoS Exec Code Overflow | G50: 6.8
... A59: llama3.2:3b | B59: 57 | C59: 81 | D59: 6.2242889 | E59: CPP | F59: DoS Exec Code Overflow | G59: 6.8
A60: llama3.2:3b | B60: 58 | C60: 80 | D60: 4.8384719 | E60: CPP | G60: 6.8
A61: llama3.2:3b | B61: 59 | C61: 12 | D61: 5.0150039 | E61: CPP | G61: 6.8
A62: llama3.2:3b | B62: 60 | C62: 80 | D62: 3.8679521 | E62: C | F62: Overflow | G62: 7.5
A63: llama3.2:3b | B63: 61 | C63: 72 | D63: 3.1703241 | E63: C | F63: Overflow | G63: 7.5
A64: llama3.2:3b | B64: 62 | C64: 80 | D64: 2.7149994 | E64: C | F64: Overflow | G64: 5
A65: llama3.2:3b | B65: 63 | C65: 83 | D65: 4.6621487 | E65: C | F65: Overflow | G65: 5
A66: llama3.2:3b | B66: 64 | C66: 89 | D66: 18.738507 | E66: C | F66: Overflow | G66: 5
A67: llama3.2:3b | B67: 65 | C67: 90 | D67: 3.6395357 | E67: C | F67: DoS | G67: 5
A68: llama3.2:3b | B68: 66 | C68: 85 | D68: 2.9548619 | E68: C | F68: DoS | G68: 5
A69: llama3.2:3b | B69: 67 | C69: 72 | D69: 3.2206454 | E69: C | F69: DoS | G69: 5
A70: llama3.2:3b | B70: 68 | C70: 80 | D70: 3.2555692 | E70: C | F70: DoS | G70: 5
...

Sheet gemma4FinalScores
A1: llmModel | B1: iteration | C1: finalScore | D1: execTime | E1: programLang | F1: vulnType | G1: vulnSeverity
A2: gemma4:e2b | B2: 0 | C2: 0 | D2: 23.108793 | E2: C | F2: Bypass | G2: 6
A3: gemma4:e2b | B3: 1 | C3: 0 | D3: 25.796602 | E3: C | F3: DoS Overflow +Info | G3: 6.4
A4: gemma4:e2b | B4: 2 | C4: 100 | D4: 11.382298 | E4: C | F4: DoS Overflow | G4: 5
A5: gemma4:e2b | B5: 3 | C5: 0 | D5: 16.634317 | E5: C | F5: DoS | G5: 4.3
A6: gemma4:e2b | B6: 4 | C6: 25 | D6: 36.961521 | E6: C | F6: DoS Exec Code Overflow Mem. Corr. | G6: 7.5
A7: gemma4:e2b | B7: 5 | C7: 100 | D7: 32.36466 | E7: C | F7: DoS Overflow | G7: 4.3
A8: gemma4:e2b | B8: 6 | C8: 100 | D8: 25.489312 | E8: C | F8: DoS Overflow | G8: 4.3
A9: gemma4:e2b | B9: 7 | C9: 90 | D9: 31.676683 | E9: C | F9: DoS | G9: 6.8
A10: gemma4:e2b | B10: 8 | C10: 100 | D10: 27.369876 | E10: C | F10: DoS | G10: 6.8
A11: gemma4:e2b | B11: 9 | C11: 0 | D11: 14.070873 | E11: C | F11: DoS | G11: 6.8
A12: gemma4:e2b | B12: 10 | C12: 100 | D12: 12.780073 | E12: C | F12: +Info | G12: 5
A13: gemma4:e2b | B13: 11 | C13: 0 | D13: 30.408362 | E13: C | F13: DoS | G13: 4.3
... A36: gemma4:e2b | B36: 34 | C36: 93 | D36: 31.561929 | E36: C | F36: Bypass | G36: 7.5
A37: gemma4:e2b | B37: 35 | C37: 15 | D37: 29.72311 | E37: C | G37: 5
A38: gemma4:e2b | B38: 36 | C38: 100 | D38: 13.183797 | E38: C | G38: 5
A39: gemma4:e2b | B39: 37 | C39: 0 | D39: 41.470896 | E39: CPP | F39: DoS Exec Code Overflow Mem. Corr. | G39: 9.3
A40: gemma4:e2b | B40: 38 | C40: 100 | D40: 30.519728 | E40: CPP | F40: DoS Exec Code Overflow | G40: 6.8
A41: gemma4:e2b | B41: 39 | C41: 100 | D41: 43.590947 | E41: CPP | F41: DoS Exec Code Overflow | G41: 6.8
A42: gemma4:e2b | B42: 40 | C42: 100 | D42: 18.442781 | E42: CPP | F42: DoS Exec Code Overflow | G42: 6.8
A43: gemma4:e2b | B43: 41 | C43: 100 | D43: 31.097557 | E43: CPP | F43: DoS Exec Code Overflow | G43: 6.8
A44: gemma4:e2b | B44: 42 | C44: 55 | D44: 30.021306 | E44: CPP | F44: DoS Exec Code Overflow | G44: 6.8
A45: gemma4:e2b | B45: 43 | C45: 100 | D45: 29.869007 | E45: CPP | F45: DoS Exec Code Overflow | G45: 6.8
A46: gemma4:e2b | B46: 44 | C46: 100 | D46: 30.918865 | E46: CPP | F46: DoS Exec Code Overflow | G46: 6.8
A47: gemma4:e2b | B47: 45 | C47: 100 | D47: 35.450999 | E47: CPP | F47: DoS Exec Code Overflow | G47: 6.8
A48: gemma4:e2b | B48: 46 | C48: 100 | D48: 23.999194 | E48: CPP | F48: DoS Exec Code Overflow | G48: 6.8
A49: gemma4:e2b | B49: 47 | C49: 100 | D49: 40.507028 | E49: CPP | F49: DoS Exec Code Overflow | G49: 6.8
A50: gemma4:e2b | B50: 48 | C50: 60 | D50: 18.104428 | E50: CPP | F50: DoS Exec Code Overflow | G50: 6.8
... A59: gemma4:e2b | B59: 57 | C59: 100 | D59: 560.97176 | E59: CPP | F59: DoS Exec Code Overflow | G59: 6.8
A60: gemma4:e2b | B60: 58 | C60: 70 | D60: 27.588475 | E60: CPP | G60: 6.8
A61: gemma4:e2b | B61: 59 | C61: 100 | D61: 39.635565 | E61: CPP | G61: 6.8
A62: gemma4:e2b | B62: 60 | C62: 35 | D62: 32.224235 | E62: C | F62: Overflow | G62: 7.5
A63: gemma4:e2b | B63: 61 | C63: 20 | D63: 21.745071 | E63: C | F63: Overflow | G63: 7.5
A64: gemma4:e2b | B64: 62 | C64: 50 | D64: 14.852407 | E64: C | F64: Overflow | G64: 5
A65: gemma4:e2b | B65: 63 | C65: 96 | D65: 22.930022 | E65: C | F65: Overflow | G65: 5
A66: gemma4:e2b | B66: 64 | C66: 100 | D66: 32.747675 | E66: C | F66: Overflow | G66: 5
A67: gemma4:e2b | B67: 65 | C67: 50 | D67: 20.841614 | E67: C | F67: DoS | G67: 5
A68: gemma4:e2b | B68: 66 | C68: 0 | D68: 22.98392 | E68: C | F68: DoS | G68: 5
A69: gemma4:e2b | B69: 67 | C69: 100 | D69: 21.020496 | E69: C | F69: DoS | G69: 5
A70: gemma4:e2b | B70: 68 | C70: 100 | D70: 25.106867 | E70: C | F70: DoS | G70: 5
...
